Workbook

Sheet Analysis Summary
B3: Clackamas Town Center - Sales Analysis Summary
B5: Property Overview
B6: T-12 Period: | C6: ='Property Summary'!D2 -> 6/2024-5/2025 | E6: Placer Visits: | F6: ='Property Summary'!E2 -> 9376877 | H6: Trade Area Pop: | I6: ='Property Summary'!F2 -> 812175
B7: Inline Sales PSF: | C7: ='Property Summary'!I2 -> 615.0883 | E7: AHHI: | F7: ='Property Summary'!G2 -> 110808.28 | H7: Gross Rent PSF: | I7: ='Property Summary'!J2 -> 83.116846
B8: Total Occ Cost: | C8: ='Property Summary'!K2 -> 0.16065159 | E8: Set Avg Occ Cost: | F8: =AVERAGEIFS('Property Summary'!K$2:K$49,'Property Summary'!B$2:B$49,"Y",'Property Summary'!K$2:K$49,"<>") -> 0.14227871 | H8: Spread: | I8: ='Property Summary'!K2-AVERAGEIFS('Property Summary'!K$2:K$49,'Property Summary'!B$2:B$49,"Y",'Property Summary'!K$2:K$49,"<>") -> 0.018372882
B10: Methodology
B11: Comp set: 48 properties from the Select Asset Sales Comp. Inline tenants only (<10,000 SF). Sales PSF = total category sales / total category SQFT per property, averaged across set (excluding properties with $0 in category). All formulas reference the Tenant Data sheet. Toggle property inclusion on Property Summary col B.
B13: Total Inline Occupancy Cost - All Properties (Reporting Tenants Only)
B14: Property | C14: Sales PSF (ex Apple) | D14: Occ Cost | E14: Placer Visits | F14: AHHI | G14: Tenant Count
B15: Oklahoma City Collection | C15: =IF('Property Summary'!B32="Y",'Property Summary'!I32,"") -> 725.6863 | D15: =IF('Property Summary'!B32="Y",'Property Summary'!K32,"") -> 0.10212611 | E15: =IF('Property Summary'!B32="Y",'Property Summary'!E32,"") -> 6191968 | F15: =IF('Property Summary'!B32="Y",'Property Summary'!G32,"") -> 304463.27 | G15: =IF('Property Summary'!B32="Y",'Property Summary'!L32,"") -> 74
B16: Belmar | C16: =IF('Property Summary'!B6="Y",'Property Summary'!I6,"") -> 374.60868 | D16: =IF('Property Summary'!B6="Y",'Property Summary'!K6,"") -> 0.10331773 | E16: =IF('Property Summary'!B6="Y",'Property Summary'!E6,"") -> 7490755 | F16: =IF('Property Summary'!B6="Y",'Property Summary'!G6,"") -> 116194.71 | G16: =IF('Property Summary'!B6="Y",'Property Summary'!L6,"") -> 42
B17: LaCenterra at Cinco Ranch | C17: =IF('Property Summary'!B23="Y",'Property Summary'!I23,"") -> 706.70925 | D17: =IF('Property Summary'!B23="Y",'Property Summary'!K23,"") -> 0.10727303 | E17: =IF('Property Summary'!B23="Y",'Property Summary'!E23,"") -> 5076169 | F17: =IF('Property Summary'!B23="Y",'Property Summary'!G23,"") -> 144646.46 | G17: =IF('Property Summary'!B23="Y",'Property Summary'!L23,"") -> 86
B18: Bridge Street Towne Centre | C18: =IF('Property Summary'!B9="Y",'Property Summary'!I9,"") -> 606.2783 | D18: =IF('Property Summary'!B9="Y",'Property Summary'!K9,"") -> 0.1100116 | E18: =IF('Property Summary'!B9="Y",'Property Summary'!E9,"") -> 6217908 | F18: =IF('Property Summary'!B9="Y",'Property Summary'!G9,"") -> 109737.91 | G18: =IF('Property Summary'!B9="Y",'Property Summary'!L9,"") -> 70
B19: Mayfaire Town Center | C19: =IF('Property Summary'!B29="Y",'Property Summary'!I29,"") -> 484.02415 | D19: =IF('Property Summary'!B29="Y",'Property Summary'!K29,"") -> 0.11495173 | E19: =IF('Property Summary'!B29="Y",'Property Summary'!E29,"") -> 6047693 | F19: =IF('Property Summary'!B29="Y",'Property Summary'!G29,"") -> 116236.91 | G19: =IF('Property Summary'!B29="Y",'Property Summary'!L29,"") -> 73
B20: Mall at Wellington Green | C20: =IF('Property Summary'!B27="Y",'Property Summary'!I27,"") -> 496.34618 | D20: =IF('Property Summary'!B27="Y",'Property Summary'!K27,"") -> 0.11613297 | E20: =IF('Property Summary'!B27="Y",'Property Summary'!E27,"") -> 5009861 | F20: =IF('Property Summary'!B27="Y",'Property Summary'!G27,"") -> 100971.33 | G20: =IF('Property Summary'!B27="Y",'Property Summary'!L27,"") -> 83
B21: Mall at Partridge Creek | C21: =IF('Property Summary'!B25="Y",'Property Summary'!I25,"") -> 396.72978 | D21: =IF('Property Summary'!B25="Y",'Property Summary'!K25,"") -> 0.11859121 | E21: =IF('Property Summary'!B25="Y",'Property Summary'!E25,"") -> 4184715 | F21: =IF('Property Summary'!B25="Y",'Property Summary'!G25,"") -> 98824.38 | G21: =IF('Property Summary'!B25="Y",'Property Summary'!L25,"") -> 61
B22: Mesa Mall | C22: =IF('Property Summary'!B30="Y",'Property Summary'!I30,"") -> 384.09084 | D22: =IF('Property Summary'!B30="Y",'Property Summary'!K30,"") -> 0.11888943 | E22: =IF('Property Summary'!B30="Y",'Property Summary'!E30,"") -> 7396278 | F22: =IF('Property Summary'!B30="Y",'Property Summary'!G30,"") -> 86600.37 | G22: =IF('Property Summary'!B30="Y",'Property Summary'!L30,"") -> 68
B23: Hamilton Place Mall | C23: =IF('Property Summary'!B20="Y",'Property Summary'!I20,"") -> 489.11863 | D23: =IF('Property Summary'!B20="Y",'Property Summary'!K20,"") -> 0.12103796 | E23: =IF('Property Summary'!B20="Y",'Property Summary'!E20,"") -> 7021524 | F23: =IF('Property Summary'!B20="Y",'Property Summary'!G20,"") -> 99241.52 | G23: =IF('Property Summary'!B20="Y",'Property Summary'!L20,"") -> 99
B24: Willow Grove Park | C24: =IF('Property Summary'!B49="Y",'Property Summary'!I49,"") -> 557.27661 | D24: =IF('Property Summary'!B49="Y",'Property Summary'!K49,"") -> 0.12179287 | E24: =IF('Property Summary'!B49="Y",'Property Summary'!E49,"") -> 5160995 | F24: =IF('Property Summary'!B49="Y",'Property Summary'!G49,"") -> 105000 | G24: =IF('Property Summary'!B49="Y",'Property Summary'!L49,"") -> 37
B25: Scottsdale Quarter | C25: =IF('Property Summary'!B37="Y",'Property Summary'!I37,"") -> 1042.2429 | D25: =IF('Property Summary'!B37="Y",'Property Summary'!K37,"") -> 0.1220669 | E25: =IF('Property Summary'!B37="Y",'Property Summary'!E37,"") -> 4531037 | F25: =IF('Property Summary'!B37="Y",'Property Summary'!G37,"") -> 137148.56 | G25: =IF('Property Summary'!B37="Y",'Property Summary'!L37,"") -> 95
B26: West Towne Mall | C26: =IF('Property Summary'!B47="Y",'Property Summary'!I47,"") -> 404.91999 | D26: =IF('Property Summary'!B47="Y",'Property Summary'!K47,"") -> 0.12263295 | E26: =IF('Property Summary'!B47="Y",'Property Summary'!E47,"") -> 7476751 | F26: =IF('Property Summary'!B47="Y",'Property Summary'!G47,"") -> 113018.03 | G26: =IF('Property Summary'!B47="Y",'Property Summary'!L47,"") -> 76
B27: Brandon Exchange | C27: =IF('Property Summary'!B7="Y",'Property Summary'!I7,"") -> 655.83465 | D27: =IF('Property Summary'!B7="Y",'Property Summary'!K7,"") -> 0.12516513 | E27: =IF('Property Summary'!B7="Y",'Property Summary'!E7,"") -> 6850096 | F27: =IF('Property Summary'!B7="Y",'Property Summary'!G7,"") -> 93025.38 | G27: =IF('Property Summary'!B7="Y",'Property Summary'!L7,"") -> 101
B28: Pearland Town Center | C28: =IF('Property Summary'!B35="Y",'Property Summary'!I35,"") -> 383.83986 | D28: =IF('Property Summary'!B35="Y",'Property Summary'!K35,"") -> 0.12524162 | E28: =IF('Property Summary'!B35="Y",'Property Summary'!E35,"") -> 6077754 | F28: =IF('Property Summary'!B35="Y",'Property Summary'!G35,"") -> 126295.43 | G28: =IF('Property Summary'!B35="Y",'Property Summary'!L35,"") -> 91
B29: SouthPark Mall (OH) | C29: =IF('Property Summary'!B39="Y",'Property Summary'!I39,"") -> 399.91307 | D29: =IF('Property Summary'!B39="Y",'Property Summary'!K39,"") -> 0.12530479 | E29: =IF('Property Summary'!B39="Y",'Property Summary'!E39,"") -> 7531055 | F29: =IF('Property Summary'!B39="Y",'Property Summary'!G39,"") -> 88347.35 | G29: =IF('Property Summary'!B39="Y",'Property Summary'!L39,"") -> 95
B30: Crossgates Center | C30: =IF('Property Summary'!B16="Y",'Property Summary'!I16,"") -> 503.303 | D30: =IF('Property Summary'!B16="Y",'Property Summary'!K16,"") -> 0.12642244 | E30: =IF('Property Summary'!B16="Y",'Property Summary'!E16,"") -> 8839014 | F30: =IF('Property Summary'!B16="Y",'Property Summary'!G16,"") -> 100046.57 | G30: =IF('Property Summary'!B16="Y",'Property Summary'!L16,"") -> 75
B31: Oak Park Mall | C31: =IF('Property Summary'!B31="Y",'Property Summary'!I31,"") -> 561.77993 | D31: =IF('Property Summary'!B31="Y",'Property Summary'!K31,"") -> 0.12687737 | E31: =IF('Property Summary'!B31="Y",'Property Summary'!E31,"") -> 9415595 | F31: =IF('Property Summary'!B31="Y",'Property Summary'!G31,"") -> 111468.63 | G31: =IF('Property Summary'!B31="Y",'Property Summary'!L31,"") -> 107
B32: Liberty Center | C32: =IF('Property Summary'!B24="Y",'Property Summary'!I24,"") -> 430.2977 | D32: =IF('Property Summary'!B24="Y",'Property Summary'!K24,"") -> 0.12919602 | E32: =IF('Property Summary'!B24="Y",'Property Summary'!E24,"") -> 6380250 | F32: =IF('Property Summary'!B24="Y",'Property Summary'!G24,"") -> 107163.69 | G32: =IF('Property Summary'!B24="Y",'Property Summary'!L24,"") -> 71
B33: West County Center | C33: =IF('Property Summary'!B46="Y",'Property Summary'!I46,"") -> 683.68095 | D33: =IF('Property Summary'!B46="Y",'Property Summary'!K46,"") -> 0.13019321 | E33: =IF('Property Summary'!B46="Y",'Property Summary'!E46,"") -> 7072500 | F33: =IF('Property Summary'!B46="Y",'Property Summary'!G46,"") -> 120521 | G33: =IF('Property Summary'!B46="Y",'Property Summary'!L46,"") -> 95
B34: The Shops At Evergreen Walk | C34: =IF('Property Summary'!B42="Y",'Property Summary'!I42,"") -> 510.44745 | D34: =IF('Property Summary'!B42="Y",'Property Summary'!K42,"") -> 0.13142369 | E34: =IF('Property Summary'!B42="Y",'Property Summary'!E42,"") -> 3661226 | F34: =IF('Property Summary'!B42="Y",'Property Summary'!G42,"") -> 103025.54 | G34: =IF('Property Summary'!B42="Y",'Property Summary'!L42,"") -> 42
B35: Hanes Mall | C35: =IF('Property Summary'!B21="Y",'Property Summary'!I21,"") -> 405.40898 | D35: =IF('Property Summary'!B21="Y",'Property Summary'!K21,"") -> 0.13245697 | E35: =IF('Property Summary'!B21="Y",'Property Summary'!E21,"") -> 8597850 | F35: =IF('Property Summary'!B21="Y",'Property Summary'!G21,"") -> 86092.68 | G35: =IF('Property Summary'!B21="Y",'Property Summary'!L21,"") -> 108
B36: Annapolis Town Center | C36: =IF('Property Summary'!B4="Y",'Property Summary'!I4,"") -> 516.97672 | D36: =IF('Property Summary'!B4="Y",'Property Summary'!K4,"") -> 0.13606986 | E36: =IF('Property Summary'!B4="Y",'Property Summary'!E4,"") -> 5278675 | F36: =IF('Property Summary'!B4="Y",'Property Summary'!G4,"") -> 158600.14 | G36: =IF('Property Summary'!B4="Y",'Property Summary'!L4,"") -> 28
B37: Coastal Grand Mall | C37: =IF('Property Summary'!B12="Y",'Property Summary'!I12,"") -> 433.53269 | D37: =IF('Property Summary'!B12="Y",'Property Summary'!K12,"") -> 0.13689809 | E37: =IF('Property Summary'!B12="Y",'Property Summary'!E12,"") -> 5952111 | F37: =IF('Property Summary'!B12="Y",'Property Summary'!G12,"") -> 89321.41 | G37: =IF('Property Summary'!B12="Y",'Property Summary'!L12,"") -> 86
B38: Mall del Norte | C38: =IF('Property Summary'!B28="Y",'Property Summary'!I28,"") -> 468.53189 | D38: =IF('Property Summary'!B28="Y",'Property Summary'!K28,"") -> 0.13763678 | E38: =IF('Property Summary'!B28="Y",'Property Summary'!E28,"") -> 6444269 | F38: =IF('Property Summary'!B28="Y",'Property Summary'!G28,"") -> 83955 | G38: =IF('Property Summary'!B28="Y",'Property Summary'!L28,"") -> 70
B39: Fayette Mall | C39: =IF('Property Summary'!B18="Y",'Property Summary'!I18,"") -> 513.06433 | D39: =IF('Property Summary'!B18="Y",'Property Summary'!K18,"") -> 0.13856449 | E39: =IF('Property Summary'!B18="Y",'Property Summary'!E18,"") -> 7576017 | F39: =IF('Property Summary'!B18="Y",'Property Summary'!G18,"") -> 97053.18 | G39: =IF('Property Summary'!B18="Y",'Property Summary'!L18,"") -> 101
B40: Capital City Mall | C40: =IF('Property Summary'!B11="Y",'Property Summary'!I11,"") -> 467.54888 | D40: =IF('Property Summary'!B11="Y",'Property Summary'!K11,"") -> 0.14143738 | E40: =IF('Property Summary'!B11="Y",'Property Summary'!E11,"") -> 4655717 | F40: =IF('Property Summary'!B11="Y",'Property Summary'!G11,"") -> 99569 | G40: =IF('Property Summary'!B11="Y",'Property Summary'!L11,"") -> 71
B41: Providence Place | C41: =IF('Property Summary'!B36="Y",'Property Summary'!I36,"") -> 543.60095 | D41: =IF('Property Summary'!B36="Y",'Property Summary'!K36,"") -> 0.14178105 | E41: =IF('Property Summary'!B36="Y",'Property Summary'!E36,"") -> 6728617 | F41: =IF('Property Summary'!B36="Y",'Property Summary'!G36,"") -> 96480.19 | G41: =IF('Property Summary'!B36="Y",'Property Summary'!L36,"") -> 64
B42: Paddock Mall | C42: =IF('Property Summary'!B33="Y",'Property Summary'!I33,"") -> 542.2408 | D42: =IF('Property Summary'!B33="Y",'Property Summary'!K33,"") -> 0.14252952 | E42: =IF('Property Summary'!B33="Y",'Property Summary'!E33,"") -> 3312527 | F42: =IF('Property Summary'!B33="Y",'Property Summary'!G33,"") -> 82408 | G42: =IF('Property Summary'!B33="Y",'Property Summary'!L33,"") -> 59
B43: Southgate Mall | C43: =IF('Property Summary'!B40="Y",'Property Summary'!I40,"") -> 356.40139 | D43: =IF('Property Summary'!B40="Y",'Property Summary'!K40,"") -> 0.14360092 | E43: =IF('Property Summary'!B40="Y",'Property Summary'!E40,"") -> 5040890 | F43: =IF('Property Summary'!B40="Y",'Property Summary'!G40,"") -> 93119.05 | G43: =IF('Property Summary'!B40="Y",'Property Summary'!L40,"") -> 48
B44: CoolSprings Galleria | C44: =IF('Property Summary'!B13="Y",'Property Summary'!I13,"") -> 542.23444 | D44: =IF('Property Summary'!B13="Y",'Property Summary'!K13,"") -> 0.14441173 | E44: =IF('Property Summary'!B13="Y",'Property Summary'!E13,"") -> 5760072 | F44: =IF('Property Summary'!B13="Y",'Property Summary'!G13,"") -> 148339.87 | G44: =IF('Property Summary'!B13="Y",'Property Summary'!L13,"") -> 112
B45: Crabtree Valley Mall | C45: =IF('Property Summary'!B14="Y",'Property Summary'!I14,"") -> 794.4337 | D45: =IF('Property Summary'!B14="Y",'Property Summary'!K14,"") -> 0.1457247 | E45: =IF('Property Summary'!B14="Y",'Property Summary'!E14,"") -> 8462931 | F45: =IF('Property Summary'!B14="Y",'Property Summary'!G14,"") -> 122880.68 | G45: =IF('Property Summary'!B14="Y",'Property Summary'!L14,"") -> 90
...

Sheet Property Summary
A1: Property | B1: Include | C1: Property Type | D1: T-12 Period | E1: Placer Visits | F1: Trade Area Pop | G1: AHHI | H1: Inline Sales PSF | I1: Inline Sales PSF (ex Apple) | J1: Inline Rent PSF | K1: Inline Occ Cost % | L1: Inline Count
A2: Clackamas Town Center | B2: Y | C2: Enclosed Mall | D2: 6/2024-5/2025 | E2: 9376877 | F2: 812175 | G2: 110808.28 | H2: =IF(B2="Y",IFERROR(SUMIFS('Tenant Data'!$F$2:$F$4674,'Tenant Data'!$A$2:$A$4674,A2,'Tenant Data'!$F$2:$F$4674,">0",'Tenant Data'!$E$2:$E$4674,"<10000")/SUMIFS('Tenant Data'!$E$2:$E$4674,'Tenant Data'!$A$2:$A$4674,A2,'Tenant Data'!$F$2:$F$4674,">0",'Tenant Data'!$E$2:$E$4674,"<10000"),""),"") -> 615.0883 | I2: =IF(B2="Y",IFERROR(SUMIFS('Tenant Data'!$F$2:$F$4674,'Tenant Data'!$A$2:$A$4674,A2,'Tenant Data'!$D$2:$D$4674,"<>Apple",'Tenant Data'!$F$2:$F$4674,">0",'Tenant Data'!$E$2:$E$4674,"<10000")/SUMIFS('Tenant Data'!$E$2:$E$4674,'Tenant Data'!$A$2:$A$4674,A2,'Tenant Data'!$D$2:$D$4674,"<>Apple",'Tenant Data'!$F$2:$F$4674,">0",'Tenant Data'!$E$2:$E$4674,"<10000"),""),"") -> 615.0883 | J2: =IF(B2="Y",IFERROR(SUMPRODUCT(('Tenant Data'!$A$2:$A$4674=A2)*('Tenant Data'!$F$2:$F$4674>0)*('Tenant Data'!$E$2:$E$4674<10000)*'Tenant Data'!$I$2:$I$4674*'Tenant Data'!$E$2:$E$4674)/SUMPRODUCT(('Tenant Data'!$A$2:$A$4674=A2)*('Tenant Data'!$F$2:$F$4674>0)*('Tenant Data'!$E$2:$E$4674<10000)*'Tenant Data'!$E$2:$E$4674),""),"") -> 83.116846 | K2: =IF(B2="Y",IFERROR(SUMPRODUCT(('Tenant Data'!$A$2:$A$4674=A2)*('Tenant Data'!$F$2:$F$4674>0)*('Tenant Data'!$E$2:$E$4674<10000)*'Tenant Data'!$J$2:$J$4674*'Tenant Data'!$E$2:$E$4674)/SUMPRODUCT(('Tenant Data'!$A$2:$A$4674=A2)*('Tenant Data'!$F$2:$F$4674>0)*('Tenant Data'!$E$2:$E$4674<10000)*'Tenant Data'!$E$2:$E$4674),""),"") -> 0.16065159 | L2: =IF(B2="Y",COUNTIFS('Tenant Data'!$A$2:$A$4674,A2,'Tenant Data'!$E$2:$E$4674,"<10000"),"") -> 109
A3: Annapolis Mall | B3: Y | C3: Enclosed Mall | D3: 2/2022-1/2023 | E3: 7274990 | F3: 841572 | G3: 139445.69 | H3: =IF(B3="Y",IFERROR(SUMIFS('Tenant Data'!$F$2:$F$4674,'Tenant Data'!$A$2:$A$4674,A3,'Tenant Data'!$F$2:$F$4674,">0",'Tenant Data'!$E$2:$E$4674,"<10000")/SUMIFS('Tenant Data'!$E$2:$E$4674,'Tenant Data'!$A$2:$A$4674,A3,'Tenant Data'!$F$2:$F$4674,">0",'Tenant Data'!$E$2:$E$4674,"<10000"),""),"") -> 620.13578 | I3: =IF(B3="Y",IFERROR(SUMIFS('Tenant Data'!$F$2:$F$4674,'Tenant Data'!$A$2:$A$4674,A3,'Tenant Data'!$D$2:$D$4674,"<>Apple",'Tenant Data'!$F$2:$F$4674,">0",'Tenant Data'!$E$2:$E$4674,"<10000")/SUMIFS('Tenant Data'!$E$2:$E$4674,'Tenant Data'!$A$2:$A$4674,A3,'Tenant Data'!$D$2:$D$4674,"<>Apple",'Tenant Data'!$F$2:$F$4674,">0",'Tenant Data'!$E$2:$E$4674,"<10000"),""),"") -> 522.44917 | J3: =IF(B3="Y",IFERROR(SUMPRODUCT(('Tenant Data'!$A$2:$A$4674=A3)*('Tenant Data'!$F$2:$F$4674>0)*('Tenant Data'!$E$2:$E$4674<10000)*'Tenant Data'!$I$2:$I$4674*'Tenant Data'!$E$2:$E$4674)/SUMPRODUCT(('Tenant Data'!$A$2:$A$4674=A3)*('Tenant Data'!$F$2:$F$4674>0)*('Tenant Data'!$E$2:$E$4674<10000)*'Tenant Data'!$E$2:$E$4674),""),"") -> 78.405891 | K3: =IF(B3="Y",IFERROR(SUMPRODUCT(('Tenant Data'!$A$2:$A$4674=A3)*('Tenant Data'!$F$2:$F$4674>0)*('Tenant Data'!$E$2:$E$4674<10000)*'Tenant Data'!$J$2:$J$4674*'Tenant Data'!$E$2:$E$4674)/SUMPRODUCT(('Tenant Data'!$A$2:$A$4674=A3)*('Tenant Data'!$F$2:$F$4674>0)*('Tenant Data'!$E$2:$E$4674<10000)*'Tenant Data'!$E$2:$E$4674),""),"") -> 0.18015803 | L3: =IF(B3="Y",COUNTIFS('Tenant Data'!$A$2:$A$4674,A3,'Tenant Data'!$E$2:$E$4674,"<10000"),"") -> 109
A4: Annapolis Town Center | B4: Y | C4: Open Air | D4: 3/2023-2/2024 | E4: 5278675 | F4: 342233 | G4: 158600.14 | H4: =IF(B4="Y",IFERROR(SUMIFS('Tenant Data'!$F$2:$F$4674,'Tenant Data'!$A$2:$A$4674,A4,'Tenant Data'!$F$2:$F$4674,">0",'Tenant Data'!$E$2:$E$4674,"<10000")/SUMIFS('Tenant Data'!$E$2:$E$4674,'Tenant Data'!$A$2:$A$4674,A4,'Tenant Data'!$F$2:$F$4674,">0",'Tenant Data'!$E$2:$E$4674,"<10000"),""),"") -> 516.97672 | I4: =IF(B4="Y",IFERROR(SUMIFS('Tenant Data'!$F$2:$F$4674,'Tenant Data'!$A$2:$A$4674,A4,'Tenant Data'!$D$2:$D$4674,"<>Apple",'Tenant Data'!$F$2:$F$4674,">0",'Tenant Data'!$E$2:$E$4674,"<10000")/SUMIFS('Tenant Data'!$E$2:$E$4674,'Tenant Data'!$A$2:$A$4674,A4,'Tenant Data'!$D$2:$D$4674,"<>Apple",'Tenant Data'!$F$2:$F$4674,">0",'Tenant Data'!$E$2:$E$4674,"<10000"),""),"") -> 516.97672 | J4: =IF(B4="Y",IFERROR(SUMPRODUCT(('Tenant Data'!$A$2:$A$4674=A4)*('Tenant Data'!$F$2:$F$4674>0)*('Tenant Data'!$E$2:$E$4674<10000)*'Tenant Data'!$I$2:$I$4674*'Tenant Data'!$E$2:$E$4674)/SUMPRODUCT(('Tenant Data'!$A$2:$A$4674=A4)*('Tenant Data'!$F$2:$F$4674>0)*('Tenant Data'!$E$2:$E$4674<10000)*'Tenant Data'!$E$2:$E$4674),""),"") -> 48.304069 | K4: =IF(B4="Y",IFERROR(SUMPRODUCT(('Tenant Data'!$A$2:$A$4674=A4)*('Tenant Data'!$F$2:$F$4674>0)*('Tenant Data'!$E$2:$E$4674<10000)*'Tenant Data'!$J$2:$J$4674*'Tenant Data'!$E$2:$E$4674)/SUMPRODUCT(('Tenant Data'!$A$2:$A$4674=A4)*('Tenant Data'!$F$2:$F$4674>0)*('Tenant Data'!$E$2:$E$4674<10000)*'Tenant Data'!$E$2:$E$4674),""),"") -> 0.13606986 | L4: =IF(B4="Y",COUNTIFS('Tenant Data'!$A$2:$A$4674,A4,'Tenant Data'!$E$2:$E$4674,"<10000"),"") -> 28
A5: Arden Fair Mall | B5: Y | C5: Enclosed Mall | D5: 3/2023-2/2024 | E5: 7097365 | F5: 1081269 | G5: 105913.35 | H5: =IF(B5="Y",IFERROR(SUMIFS('Tenant Data'!$F$2:$F$4674,'Tenant Data'!$A$2:$A$4674,A5,'Tenant Data'!$F$2:$F$4674,">0",'Tenant Data'!$E$2:$E$4674,"<10000")/SUMIFS('Tenant Data'!$E$2:$E$4674,'Tenant Data'!$A$2:$A$4674,A5,'Tenant Data'!$F$2:$F$4674,">0",'Tenant Data'!$E$2:$E$4674,"<10000"),""),"") -> 841.96341 | I5: =IF(B5="Y",IFERROR(SUMIFS('Tenant Data'!$F$2:$F$4674,'Tenant Data'!$A$2:$A$4674,A5,'Tenant Data'!$D$2:$D$4674,"<>Apple",'Tenant Data'!$F$2:$F$4674,">0",'Tenant Data'!$E$2:$E$4674,"<10000")/SUMIFS('Tenant Data'!$E$2:$E$4674,'Tenant Data'!$A$2:$A$4674,A5,'Tenant Data'!$D$2:$D$4674,"<>Apple",'Tenant Data'!$F$2:$F$4674,">0",'Tenant Data'!$E$2:$E$4674,"<10000"),""),"") -> 690.82267 | J5: =IF(B5="Y",IFERROR(SUMPRODUCT(('Tenant Data'!$A$2:$A$4674=A5)*('Tenant Data'!$F$2:$F$4674>0)*('Tenant Data'!$E$2:$E$4674<10000)*'Tenant Data'!$I$2:$I$4674*'Tenant Data'!$E$2:$E$4674)/SUMPRODUCT(('Tenant Data'!$A$2:$A$4674=A5)*('Tenant Data'!$F$2:$F$4674>0)*('Tenant Data'!$E$2:$E$4674<10000)*'Tenant Data'!$E$2:$E$4674),""),"") -> 97.873362 | K5: =IF(B5="Y",IFERROR(SUMPRODUCT(('Tenant Data'!$A$2:$A$4674=A5)*('Tenant Data'!$F$2:$F$4674>0)*('Tenant Data'!$E$2:$E$4674<10000)*'Tenant Data'!$J$2:$J$4674*'Tenant Data'!$E$2:$E$4674)/SUMPRODUCT(('Tenant Data'!$A$2:$A$4674=A5)*('Tenant Data'!$F$2:$F$4674>0)*('Tenant Data'!$E$2:$E$4674<10000)*'Tenant Data'!$E$2:$E$4674),""),"") -> 0.1590532 | L5: =IF(B5="Y",COUNTIFS('Tenant Data'!$A$2:$A$4674,A5,'Tenant Data'!$E$2:$E$4674,"<10000"),"") -> 78
A6: Belmar | B6: Y | C6: Open Air | D6: 11/2019-10/2020 | E6: 7490755 | F6: 398730 | G6: 116194.71 | H6: =IF(B6="Y",IFERROR(SUMIFS('Tenant Data'!$F$2:$F$4674,'Tenant Data'!$A$2:$A$4674,A6,'Tenant Data'!$F$2:$F$4674,">0",'Tenant Data'!$E$2:$E$4674,"<10000")/SUMIFS('Tenant Data'!$E$2:$E$4674,'Tenant Data'!$A$2:$A$4674,A6,'Tenant Data'!$F$2:$F$4674,">0",'Tenant Data'!$E$2:$E$4674,"<10000"),""),"") -> 374.60868 | I6: =IF(B6="Y",IFERROR(SUMIFS('Tenant Data'!$F$2:$F$4674,'Tenant Data'!$A$2:$A$4674,A6,'Tenant Data'!$D$2:$D$4674,"<>Apple",'Tenant Data'!$F$2:$F$4674,">0",'Tenant Data'!$E$2:$E$4674,"<10000")/SUMIFS('Tenant Data'!$E$2:$E$4674,'Tenant Data'!$A$2:$A$4674,A6,'Tenant Data'!$D$2:$D$4674,"<>Apple",'Tenant Data'!$F$2:$F$4674,">0",'Tenant Data'!$E$2:$E$4674,"<10000"),""),"") -> 374.60868 | J6: =IF(B6="Y",IFERROR(SUMPRODUCT(('Tenant Data'!$A$2:$A$4674=A6)*('Tenant Data'!$F$2:$F$4674>0)*('Tenant Data'!$E$2:$E$4674<10000)*'Tenant Data'!$I$2:$I$4674*'Tenant Data'!$E$2:$E$4674)/SUMPRODUCT(('Tenant Data'!$A$2:$A$4674=A6)*('Tenant Data'!$F$2:$F$4674>0)*('Tenant Data'!$E$2:$E$4674<10000)*'Tenant Data'!$E$2:$E$4674),""),"") -> 35.03578 | K6: =IF(B6="Y",IFERROR(SUMPRODUCT(('Tenant Data'!$A$2:$A$4674=A6)*('Tenant Data'!$F$2:$F$4674>0)*('Tenant Data'!$E$2:$E$4674<10000)*'Tenant Data'!$J$2:$J$4674*'Tenant Data'!$E$2:$E$4674)/SUMPRODUCT(('Tenant Data'!$A$2:$A$4674=A6)*('Tenant Data'!$F$2:$F$4674>0)*('Tenant Data'!$E$2:$E$4674<10000)*'Tenant Data'!$E$2:$E$4674),""),"") -> 0.10331773 | L6: =IF(B6="Y",COUNTIFS('Tenant Data'!$A$2:$A$4674,A6,'Tenant Data'!$E$2:$E$4674,"<10000"),"") -> 42
A7: Brandon Exchange | B7: Y | C7: Enclosed Mall | D7: 7/2020-6/2021 | E7: 6850096 | F7: 698081 | G7: 93025.38 | H7: =IF(B7="Y",IFERROR(SUMIFS('Tenant Data'!$F$2:$F$4674,'Tenant Data'!$A$2:$A$4674,A7,'Tenant Data'!$F$2:$F$4674,">0",'Tenant Data'!$E$2:$E$4674,"<10000")/SUMIFS('Tenant Data'!$E$2:$E$4674,'Tenant Data'!$A$2:$A$4674,A7,'Tenant Data'!$F$2:$F$4674,">0",'Tenant Data'!$E$2:$E$4674,"<10000"),""),"") -> 807.12334 | I7: =IF(B7="Y",IFERROR(SUMIFS('Tenant Data'!$F$2:$F$4674,'Tenant Data'!$A$2:$A$4674,A7,'Tenant Data'!$D$2:$D$4674,"<>Apple",'Tenant Data'!$F$2:$F$4674,">0",'Tenant Data'!$E$2:$E$4674,"<10000")/SUMIFS('Tenant Data'!$E$2:$E$4674,'Tenant Data'!$A$2:$A$4674,A7,'Tenant Data'!$D$2:$D$4674,"<>Apple",'Tenant Data'!$F$2:$F$4674,">0",'Tenant Data'!$E$2:$E$4674,"<10000"),""),"") -> 655.83465 | J7: =IF(B7="Y",IFERROR(SUMPRODUCT(('Tenant Data'!$A$2:$A$4674=A7)*('Tenant Data'!$F$2:$F$4674>0)*('Tenant Data'!$E$2:$E$4674<10000)*'Tenant Data'!$I$2:$I$4674*'Tenant Data'!$E$2:$E$4674)/SUMPRODUCT(('Tenant Data'!$A$2:$A$4674=A7)*('Tenant Data'!$F$2:$F$4674>0)*('Tenant Data'!$E$2:$E$4674<10000)*'Tenant Data'!$E$2:$E$4674),""),"") -> 77.703159 | K7: =IF(B7="Y",IFERROR(SUMPRODUCT(('Tenant Data'!$A$2:$A$4674=A7)*('Tenant Data'!$F$2:$F$4674>0)*('Tenant Data'!$E$2:$E$4674<10000)*'Tenant Data'!$J$2:$J$4674*'Tenant Data'!$E$2:$E$4674)/SUMPRODUCT(('Tenant Data'!$A$2:$A$4674=A7)*('Tenant Data'!$F$2:$F$4674>0)*('Tenant Data'!$E$2:$E$4674<10000)*'Tenant Data'!$E$2:$E$4674),""),"") -> 0.12516513 | L7: =IF(B7="Y",COUNTIFS('Tenant Data'!$A$2:$A$4674,A7,'Tenant Data'!$E$2:$E$4674,"<10000"),"") -> 101
A8: Briarwood Mall | B8: Y | C8: Enclosed Mall | D8: 10/2021-9/2022 | E8: 3417309 | F8: 438493 | G8: 112360.61 | H8: =IF(B8="Y",IFERROR(SUMIFS('Tenant Data'!$F$2:$F$4674,'Tenant Data'!$A$2:$A$4674,A8,'Tenant Data'!$F$2:$F$4674,">0",'Tenant Data'!$E$2:$E$4674,"<10000")/SUMIFS('Tenant Data'!$E$2:$E$4674,'Tenant Data'!$A$2:$A$4674,A8,'Tenant Data'!$F$2:$F$4674,">0",'Tenant Data'!$E$2:$E$4674,"<10000"),""),"") -> 45.800694 | I8: =IF(B8="Y",IFERROR(SUMIFS('Tenant Data'!$F$2:$F$4674,'Tenant Data'!$A$2:$A$4674,A8,'Tenant Data'!$D$2:$D$4674,"<>Apple",'Tenant Data'!$F$2:$F$4674,">0",'Tenant Data'!$E$2:$E$4674,"<10000")/SUMIFS('Tenant Data'!$E$2:$E$4674,'Tenant Data'!$A$2:$A$4674,A8,'Tenant Data'!$D$2:$D$4674,"<>Apple",'Tenant Data'!$F$2:$F$4674,">0",'Tenant Data'!$E$2:$E$4674,"<10000"),""),"") -> 36.056095 | J8: =IF(B8="Y",IFERROR(SUMPRODUCT(('Tenant Data'!$A$2:$A$4674=A8)*('Tenant Data'!$F$2:$F$4674>0)*('Tenant Data'!$E$2:$E$4674<10000)*'Tenant Data'!$I$2:$I$4674*'Tenant Data'!$E$2:$E$4674)/SUMPRODUCT(('Tenant Data'!$A$2:$A$4674=A8)*('Tenant Data'!$F$2:$F$4674>0)*('Tenant Data'!$E$2:$E$4674<10000)*'Tenant Data'!$E$2:$E$4674),""),"") -> 0 | K8: =IF(B8="Y",IFERROR(SUMPRODUCT(('Tenant Data'!$A$2:$A$4674=A8)*('Tenant Data'!$F$2:$F$4674>0)*('Tenant Data'!$E$2:$E$4674<10000)*'Tenant Data'!$J$2:$J$4674*'Tenant Data'!$E$2:$E$4674)/SUMPRODUCT(('Tenant Data'!$A$2:$A$4674=A8)*('Tenant Data'!$F$2:$F$4674>0)*('Tenant Data'!$E$2:$E$4674<10000)*'Tenant Data'!$E$2:$E$4674),""),"") -> 0 | L8: =IF(B8="Y",COUNTIFS('Tenant Data'!$A$2:$A$4674,A8,'Tenant Data'!$E$2:$E$4674,"<10000"),"") -> 67
A9: Bridge Street Towne Centre | B9: Y | C9: Open Air | D9: 3/2022-2/2023 | E9: 6217908 | F9: 403025 | G9: 109737.91 | H9: =IF(B9="Y",IFERROR(SUMIFS('Tenant Data'!$F$2:$F$4674,'Tenant Data'!$A$2:$A$4674,A9,'Tenant Data'!$F$2:$F$4674,">0",'Tenant Data'!$E$2:$E$4674,"<10000")/SUMIFS('Tenant Data'!$E$2:$E$4674,'Tenant Data'!$A$2:$A$4674,A9,'Tenant Data'!$F$2:$F$4674,">0",'Tenant Data'!$E$2:$E$4674,"<10000"),""),"") -> 767.89327 | I9: =IF(B9="Y",IFERROR(SUMIFS('Tenant Data'!$F$2:$F$4674,'Tenant Data'!$A$2:$A$4674,A9,'Tenant Data'!$D$2:$D$4674,"<>Apple",'Tenant Data'!$F$2:$F$4674,">0",'Tenant Data'!$E$2:$E$4674,"<10000")/SUMIFS('Tenant Data'!$E$2:$E$4674,'Tenant Data'!$A$2:$A$4674,A9,'Tenant Data'!$D$2:$D$4674,"<>Apple",'Tenant Data'!$F$2:$F$4674,">0",'Tenant Data'!$E$2:$E$4674,"<10000"),""),"") -> 606.2783 | J9: =IF(B9="Y",IFERROR(SUMPRODUCT(('Tenant Data'!$A$2:$A$4674=A9)*('Tenant Data'!$F$2:$F$4674>0)*('Tenant Data'!$E$2:$E$4674<10000)*'Tenant Data'!$I$2:$I$4674*'Tenant Data'!$E$2:$E$4674)/SUMPRODUCT(('Tenant Data'!$A$2:$A$4674=A9)*('Tenant Data'!$F$2:$F$4674>0)*('Tenant Data'!$E$2:$E$4674<10000)*'Tenant Data'!$E$2:$E$4674),""),"") -> 52.902947 | K9: =IF(B9="Y",IFERROR(SUMPRODUCT(('Tenant Data'!$A$2:$A$4674=A9)*('Tenant Data'!$F$2:$F$4674>0)*('Tenant Data'!$E$2:$E$4674<10000)*'Tenant Data'!$J$2:$J$4674*'Tenant Data'!$E$2:$E$4674)/SUMPRODUCT(('Tenant Data'!$A$2:$A$4674=A9)*('Tenant Data'!$F$2:$F$4674>0)*('Tenant Data'!$E$2:$E$4674<10000)*'Tenant Data'!$E$2:$E$4674),""),"") -> 0.1100116 | L9: =IF(B9="Y",COUNTIFS('Tenant Data'!$A$2:$A$4674,A9,'Tenant Data'!$E$2:$E$4674,"<10000"),"") -> 70
A10: Bridgewater Commons | B10: Y | C10: Enclosed Mall | D10: 7/2021-6/2022 | E10: 5816055 | F10: 912121 | G10: 161034.37 | H10: =IF(B10="Y",IFERROR(SUMIFS('Tenant Data'!$F$2:$F$4674,'Tenant Data'!$A$2:$A$4674,A10,'Tenant Data'!$F$2:$F$4674,">0",'Tenant Data'!$E$2:$E$4674,"<10000")/SUMIFS('Tenant Data'!$E$2:$E$4674,'Tenant Data'!$A$2:$A$4674,A10,'Tenant Data'!$F$2:$F$4674,">0",'Tenant Data'!$E$2:$E$4674,"<10000"),""),"") -> 745.41106 | I10: =IF(B10="Y",IFERROR(SUMIFS('Tenant Data'!$F$2:$F$4674,'Tenant Data'!$A$2:$A$4674,A10,'Tenant Data'!$D$2:$D$4674,"<>Apple",'Tenant Data'!$F$2:$F$4674,">0",'Tenant Data'!$E$2:$E$4674,"<10000")/SUMIFS('Tenant Data'!$E$2:$E$4674,'Tenant Data'!$A$2:$A$4674,A10,'Tenant Data'!$D$2:$D$4674,"<>Apple",'Tenant Data'!$F$2:$F$4674,">0",'Tenant Data'!$E$2:$E$4674,"<10000"),""),"") -> 606.70036 | J10: =IF(B10="Y",IFERROR(SUMPRODUCT(('Tenant Data'!$A$2:$A$4674=A10)*('Tenant Data'!$F$2:$F$4674>0)*('Tenant Data'!$E$2:$E$4674<10000)*'Tenant Data'!$I$2:$I$4674*'Tenant Data'!$E$2:$E$4674)/SUMPRODUCT(('Tenant Data'!$A$2:$A$4674=A10)*('Tenant Data'!$F$2:$F$4674>0)*('Tenant Data'!$E$2:$E$4674<10000)*'Tenant Data'!$E$2:$E$4674),""),"") -> 84.846944 | K10: =IF(B10="Y",IFERROR(SUMPRODUCT(('Tenant Data'!$A$2:$A$4674=A10)*('Tenant Data'!$F$2:$F$4674>0)*('Tenant Data'!$E$2:$E$4674<10000)*'Tenant Data'!$J$2:$J$4674*'Tenant Data'!$E$2:$E$4674)/SUMPRODUCT(('Tenant Data'!$A$2:$A$4674=A10)*('Tenant Data'!$F$2:$F$4674>0)*('Tenant Data'!$E$2:$E$4674<10000)*'Tenant Data'!$E$2:$E$4674),""),"") -> 0.1564615 | L10: =IF(B10="Y",COUNTIFS('Tenant Data'!$A$2:$A$4674,A10,'Tenant Data'!$E$2:$E$4674,"<10000"),"") -> 106
A11: Capital City Mall | B11: Y | C11: Enclosed Mall | D11: 5/2024-6/2025 | E11: 4655717 | F11: 319614 | G11: 99569 | H11: =IF(B11="Y",IFERROR(SUMIFS('Tenant Data'!$F$2:$F$4674,'Tenant Data'!$A$2:$A$4674,A11,'Tenant Data'!$F$2:$F$4674,">0",'Tenant Data'!$E$2:$E$4674,"<10000")/SUMIFS('Tenant Data'!$E$2:$E$4674,'Tenant Data'!$A$2:$A$4674,A11,'Tenant Data'!$F$2:$F$4674,">0",'Tenant Data'!$E$2:$E$4674,"<10000"),""),"") -> 467.54888 | I11: =IF(B11="Y",IFERROR(SUMIFS('Tenant Data'!$F$2:$F$4674,'Tenant Data'!$A$2:$A$4674,A11,'Tenant Data'!$D$2:$D$4674,"<>Apple",'Tenant Data'!$F$2:$F$4674,">0",'Tenant Data'!$E$2:$E$4674,"<10000")/SUMIFS('Tenant Data'!$E$2:$E$4674,'Tenant Data'!$A$2:$A$4674,A11,'Tenant Data'!$D$2:$D$4674,"<>Apple",'Tenant Data'!$F$2:$F$4674,">0",'Tenant Data'!$E$2:$E$4674,"<10000"),""),"") -> 467.54888 | J11: =IF(B11="Y",IFERROR(SUMPRODUCT(('Tenant Data'!$A$2:$A$4674=A11)*('Tenant Data'!$F$2:$F$4674>0)*('Tenant Data'!$E$2:$E$4674<10000)*'Tenant Data'!$I$2:$I$4674*'Tenant Data'!$E$2:$E$4674)/SUMPRODUCT(('Tenant Data'!$A$2:$A$4674=A11)*('Tenant Data'!$F$2:$F$4674>0)*('Tenant Data'!$E$2:$E$4674<10000)*'Tenant Data'!$E$2:$E$4674),""),"") -> 61.929994 | K11: =IF(B11="Y",IFERROR(SUMPRODUCT(('Tenant Data'!$A$2:$A$4674=A11)*('Tenant Data'!$F$2:$F$4674>0)*('Tenant Data'!$E$2:$E$4674<10000)*'Tenant Data'!$J$2:$J$4674*'Tenant Data'!$E$2:$E$4674)/SUMPRODUCT(('Tenant Data'!$A$2:$A$4674=A11)*('Tenant Data'!$F$2:$F$4674>0)*('Tenant Data'!$E$2:$E$4674<10000)*'Tenant Data'!$E$2:$E$4674),""),"") -> 0.14143738 | L11: =IF(B11="Y",COUNTIFS('Tenant Data'!$A$2:$A$4674,A11,'Tenant Data'!$E$2:$E$4674,"<10000"),"") -> 71
A12: Coastal Grand Mall | B12: Y | C12: Enclosed Mall | D12: 12/2024-11/2025 | E12: 5952111 | F12: 224112 | G12: 89321.41 | H12: =IF(B12="Y",IFERROR(SUMIFS('Tenant Data'!$F$2:$F$4674,'Tenant Data'!$A$2:$A$4674,A12,'Tenant Data'!$F$2:$F$4674,">0",'Tenant Data'!$E$2:$E$4674,"<10000")/SUMIFS('Tenant Data'!$E$2:$E$4674,'Tenant Data'!$A$2:$A$4674,A12,'Tenant Data'!$F$2:$F$4674,">0",'Tenant Data'!$E$2:$E$4674,"<10000"),""),"") -> 433.53269 | I12: =IF(B12="Y",IFERROR(SUMIFS('Tenant Data'!$F$2:$F$4674,'Tenant Data'!$A$2:$A$4674,A12,'Tenant Data'!$D$2:$D$4674,"<>Apple",'Tenant Data'!$F$2:$F$4674,">0",'Tenant Data'!$E$2:$E$4674,"<10000")/SUMIFS('Tenant Data'!$E$2:$E$4674,'Tenant Data'!$A$2:$A$4674,A12,'Tenant Data'!$D$2:$D$4674,"<>Apple",'Tenant Data'!$F$2:$F$4674,">0",'Tenant Data'!$E$2:$E$4674,"<10000"),""),"") -> 433.53269 | J12: =IF(B12="Y",IFERROR(SUMPRODUCT(('Tenant Data'!$A$2:$A$4674=A12)*('Tenant Data'!$F$2:$F$4674>0)*('Tenant Data'!$E$2:$E$4674<10000)*'Tenant Data'!$I$2:$I$4674*'Tenant Data'!$E$2:$E$4674)/SUMPRODUCT(('Tenant Data'!$A$2:$A$4674=A12)*('Tenant Data'!$F$2:$F$4674>0)*('Tenant Data'!$E$2:$E$4674<10000)*'Tenant Data'!$E$2:$E$4674),""),"") -> 51.28943 | K12: =IF(B12="Y",IFERROR(SUMPRODUCT(('Tenant Data'!$A$2:$A$4674=A12)*('Tenant Data'!$F$2:$F$4674>0)*('Tenant Data'!$E$2:$E$4674<10000)*'Tenant Data'!$J$2:$J$4674*'Tenant Data'!$E$2:$E$4674)/SUMPRODUCT(('Tenant Data'!$A$2:$A$4674=A12)*('Tenant Data'!$F$2:$F$4674>0)*('Tenant Data'!$E$2:$E$4674<10000)*'Tenant Data'!$E$2:$E$4674),""),"") -> 0.13689809 | L12: =IF(B12="Y",COUNTIFS('Tenant Data'!$A$2:$A$4674,A12,'Tenant Data'!$E$2:$E$4674,"<10000"),"") -> 86
A13: CoolSprings Galleria | B13: Y | C13: Enclosed Mall | D13: 12/2024-11/2025 | E13: 5760072 | F13: 744158 | G13: 148339.87 | H13: =IF(B13="Y",IFERROR(SUMIFS('Tenant Data'!$F$2:$F$4674,'Tenant Data'!$A$2:$A$4674,A13,'Tenant Data'!$F$2:$F$4674,">0",'Tenant Data'!$E$2:$E$4674,"<10000")/SUMIFS('Tenant Data'!$E$2:$E$4674,'Tenant Data'!$A$2:$A$4674,A13,'Tenant Data'!$F$2:$F$4674,">0",'Tenant Data'!$E$2:$E$4674,"<10000"),""),"") -> 695.70041 | I13: =IF(B13="Y",IFERROR(SUMIFS('Tenant Data'!$F$2:$F$4674,'Tenant Data'!$A$2:$A$4674,A13,'Tenant Data'!$D$2:$D$4674,"<>Apple",'Tenant Data'!$F$2:$F$4674,">0",'Tenant Data'!$E$2:$E$4674,"<10000")/SUMIFS('Tenant Data'!$E$2:$E$4674,'Tenant Data'!$A$2:$A$4674,A13,'Tenant Data'!$D$2:$D$4674,"<>Apple",'Tenant Data'!$F$2:$F$4674,">0",'Tenant Data'!$E$2:$E$4674,"<10000"),""),"") -> 542.23444 | J13: =IF(B13="Y",IFERROR(SUMPRODUCT(('Tenant Data'!$A$2:$A$4674=A13)*('Tenant Data'!$F$2:$F$4674>0)*('Tenant Data'!$E$2:$E$4674<10000)*'Tenant Data'!$I$2:$I$4674*'Tenant Data'!$E$2:$E$4674)/SUMPRODUCT(('Tenant Data'!$A$2:$A$4674=A13)*('Tenant Data'!$F$2:$F$4674>0)*('Tenant Data'!$E$2:$E$4674<10000)*'Tenant Data'!$E$2:$E$4674),""),"") -> 65.304581 | K13: =IF(B13="Y",IFERROR(SUMPRODUCT(('Tenant Data'!$A$2:$A$4674=A13)*('Tenant Data'!$F$2:$F$4674>0)*('Tenant Data'!$E$2:$E$4674<10000)*'Tenant Data'!$J$2:$J$4674*'Tenant Data'!$E$2:$E$4674)/SUMPRODUCT(('Tenant Data'!$A$2:$A$4674=A13)*('Tenant Data'!$F$2:$F$4674>0)*('Tenant Data'!$E$2:$E$4674<10000)*'Tenant Data'!$E$2:$E$4674),""),"") -> 0.14441173 | L13: =IF(B13="Y",COUNTIFS('Tenant Data'!$A$2:$A$4674,A13,'Tenant Data'!$E$2:$E$4674,"<10000"),"") -> 112
... A49: Willow Grove Park | B49: Y | C49: Enclosed Mall | D49: 4/2024-3/2025 | E49: 5160995 | F49: 850000 | G49: 105000 | H49: =IF(B49="Y",IFERROR(SUMIFS('Tenant Data'!$F$2:$F$4674,'Tenant Data'!$A$2:$A$4674,A49,'Tenant Data'!$F$2:$F$4674,">0",'Tenant Data'!$E$2:$E$4674,"<10000")/SUMIFS('Tenant Data'!$E$2:$E$4674,'Tenant Data'!$A$2:$A$4674,A49,'Tenant Data'!$F$2:$F$4674,">0",'Tenant Data'!$E$2:$E$4674,"<10000"),""),"") -> 827.71397 | I49: =IF(B49="Y",IFERROR(SUMIFS('Tenant Data'!$F$2:$F$4674,'Tenant Data'!$A$2:$A$4674,A49,'Tenant Data'!$D$2:$D$4674,"<>Apple",'Tenant Data'!$F$2:$F$4674,">0",'Tenant Data'!$E$2:$E$4674,"<10000")/SUMIFS('Tenant Data'!$E$2:$E$4674,'Tenant Data'!$A$2:$A$4674,A49,'Tenant Data'!$D$2:$D$4674,"<>Apple",'Tenant Data'!$F$2:$F$4674,">0",'Tenant Data'!$E$2:$E$4674,"<10000"),""),"") -> 557.27661 | J49: =IF(B49="Y",IFERROR(SUMPRODUCT(('Tenant Data'!$A$2:$A$4674=A49)*('Tenant Data'!$F$2:$F$4674>0)*('Tenant Data'!$E$2:$E$4674<10000)*'Tenant Data'!$I$2:$I$4674*'Tenant Data'!$E$2:$E$4674)/SUMPRODUCT(('Tenant Data'!$A$2:$A$4674=A49)*('Tenant Data'!$F$2:$F$4674>0)*('Tenant Data'!$E$2:$E$4674<10000)*'Tenant Data'!$E$2:$E$4674),""),"") -> 65.432632 | K49: =IF(B49="Y",IFERROR(SUMPRODUCT(('Tenant Data'!$A$2:$A$4674=A49)*('Tenant Data'!$F$2:$F$4674>0)*('Tenant Data'!$E$2:$E$4674<10000)*'Tenant Data'!$J$2:$J$4674*'Tenant Data'!$E$2:$E$4674)/SUMPRODUCT(('Tenant Data'!$A$2:$A$4674=A49)*('Tenant Data'!$F$2:$F$4674>0)*('Tenant Data'!$E$2:$E$4674<10000)*'Tenant Data'!$E$2:$E$4674),""),"") -> 0.12179287 | L49: =IF(B49="Y",COUNTIFS('Tenant Data'!$A$2:$A$4674,A49,'Tenant Data'!$E$2:$E$4674,"<10000"),"") -> 37

Sheet Tenant Lookup
A1: Tenant Sales PSF Summary
A3: Select Tenant: | B3: Lovisa
A4: # of Locations: | B4: =COUNTIF(E8:E55,">0") -> 28
A6: Property Details
A7: Property | B7: Include | C7: Size (SF) | D7: T-12 Sales | E7: Sales PSF | F7: Rent PSF | G7: Occ Cost %
A8: Clackamas Town Center | B8: ='Property Summary'!B2 -> Y | C8: =IFERROR(SUMIFS('Tenant Data'!$E$2:$E$4674,'Tenant Data'!$A$2:$A$4674,A8,'Tenant Data'!$B$2:$B$4674,$B$3),"") -> 1325 | D8: =IFERROR(SUMIFS('Tenant Data'!$F$2:$F$4674,'Tenant Data'!$A$2:$A$4674,A8,'Tenant Data'!$B$2:$B$4674,$B$3),"") -> 685034 | E8: =IFERROR(IF(C8>0,D8/C8,""),"") -> 517.00679 | F8: =IFERROR(SUMIFS('Tenant Data'!$I$2:$I$4674,'Tenant Data'!$A$2:$A$4674,A8,'Tenant Data'!$B$2:$B$4674,$B$3),"") -> 78.1542 | G8: =IFERROR(SUMIFS('Tenant Data'!$J$2:$J$4674,'Tenant Data'!$A$2:$A$4674,A8,'Tenant Data'!$B$2:$B$4674,$B$3),"") -> 0.15116668
A9: Annapolis Mall | B9: ='Property Summary'!B3 -> Y | C9: =IFERROR(SUMIFS('Tenant Data'!$E$2:$E$4674,'Tenant Data'!$A$2:$A$4674,A9,'Tenant Data'!$B$2:$B$4674,$B$3),"") -> 1160 | D9: =IFERROR(SUMIFS('Tenant Data'!$F$2:$F$4674,'Tenant Data'!$A$2:$A$4674,A9,'Tenant Data'!$B$2:$B$4674,$B$3),"") -> 368697.45 | E9: =IFERROR(IF(C9>0,D9/C9,""),"") -> 317.84263 | F9: =IFERROR(SUMIFS('Tenant Data'!$I$2:$I$4674,'Tenant Data'!$A$2:$A$4674,A9,'Tenant Data'!$B$2:$B$4674,$B$3),"") -> 92.4 | G9: =IFERROR(SUMIFS('Tenant Data'!$J$2:$J$4674,'Tenant Data'!$A$2:$A$4674,A9,'Tenant Data'!$B$2:$B$4674,$B$3),"") -> 0.2907099
A10: Annapolis Town Center | B10: ='Property Summary'!B4 -> Y | C10: =IFERROR(SUMIFS('Tenant Data'!$E$2:$E$4674,'Tenant Data'!$A$2:$A$4674,A10,'Tenant Data'!$B$2:$B$4674,$B$3),"") -> 0 | D10: =IFERROR(SUMIFS('Tenant Data'!$F$2:$F$4674,'Tenant Data'!$A$2:$A$4674,A10,'Tenant Data'!$B$2:$B$4674,$B$3),"") -> 0 | E10: =IFERROR(IF(C10>0,D10/C10,""),"") | F10: =IFERROR(SUMIFS('Tenant Data'!$I$2:$I$4674,'Tenant Data'!$A$2:$A$4674,A10,'Tenant Data'!$B$2:$B$4674,$B$3),"") -> 0 | G10: =IFERROR(SUMIFS('Tenant Data'!$J$2:$J$4674,'Tenant Data'!$A$2:$A$4674,A10,'Tenant Data'!$B$2:$B$4674,$B$3),"") -> 0
A11: Arden Fair Mall | B11: ='Property Summary'!B5 -> Y | C11: =IFERROR(SUMIFS('Tenant Data'!$E$2:$E$4674,'Tenant Data'!$A$2:$A$4674,A11,'Tenant Data'!$B$2:$B$4674,$B$3),"") -> 0 | D11: =IFERROR(SUMIFS('Tenant Data'!$F$2:$F$4674,'Tenant Data'!$A$2:$A$4674,A11,'Tenant Data'!$B$2:$B$4674,$B$3),"") -> 0 | E11: =IFERROR(IF(C11>0,D11/C11,""),"") | F11: =IFERROR(SUMIFS('Tenant Data'!$I$2:$I$4674,'Tenant Data'!$A$2:$A$4674,A11,'Tenant Data'!$B$2:$B$4674,$B$3),"") -> 0 | G11: =IFERROR(SUMIFS('Tenant Data'!$J$2:$J$4674,'Tenant Data'!$A$2:$A$4674,A11,'Tenant Data'!$B$2:$B$4674,$B$3),"") -> 0
A12: Belmar | B12: ='Property Summary'!B6 -> Y | C12: =IFERROR(SUMIFS('Tenant Data'!$E$2:$E$4674,'Tenant Data'!$A$2:$A$4674,A12,'Tenant Data'!$B$2:$B$4674,$B$3),"") -> 0 | D12: =IFERROR(SUMIFS('Tenant Data'!$F$2:$F$4674,'Tenant Data'!$A$2:$A$4674,A12,'Tenant Data'!$B$2:$B$4674,$B$3),"") -> 0 | E12: =IFERROR(IF(C12>0,D12/C12,""),"") | F12: =IFERROR(SUMIFS('Tenant Data'!$I$2:$I$4674,'Tenant Data'!$A$2:$A$4674,A12,'Tenant Data'!$B$2:$B$4674,$B$3),"") -> 0 | G12: =IFERROR(SUMIFS('Tenant Data'!$J$2:$J$4674,'Tenant Data'!$A$2:$A$4674,A12,'Tenant Data'!$B$2:$B$4674,$B$3),"") -> 0
A13: Brandon Exchange | B13: ='Property Summary'!B7 -> Y | C13: =IFERROR(SUMIFS('Tenant Data'!$E$2:$E$4674,'Tenant Data'!$A$2:$A$4674,A13,'Tenant Data'!$B$2:$B$4674,$B$3),"") -> 0 | D13: =IFERROR(SUMIFS('Tenant Data'!$F$2:$F$4674,'Tenant Data'!$A$2:$A$4674,A13,'Tenant Data'!$B$2:$B$4674,$B$3),"") -> 0 | E13: =IFERROR(IF(C13>0,D13/C13,""),"") | F13: =IFERROR(SUMIFS('Tenant Data'!$I$2:$I$4674,'Tenant Data'!$A$2:$A$4674,A13,'Tenant Data'!$B$2:$B$4674,$B$3),"") -> 0 | G13: =IFERROR(SUMIFS('Tenant Data'!$J$2:$J$4674,'Tenant Data'!$A$2:$A$4674,A13,'Tenant Data'!$B$2:$B$4674,$B$3),"") -> 0
A14: Briarwood Mall | B14: ='Property Summary'!B8 -> Y | C14: =IFERROR(SUMIFS('Tenant Data'!$E$2:$E$4674,'Tenant Data'!$A$2:$A$4674,A14,'Tenant Data'!$B$2:$B$4674,$B$3),"") -> 841 | D14: =IFERROR(SUMIFS('Tenant Data'!$F$2:$F$4674,'Tenant Data'!$A$2:$A$4674,A14,'Tenant Data'!$B$2:$B$4674,$B$3),"") -> 17900 | E14: =IFERROR(IF(C14>0,D14/C14,""),"") -> 21.284185 | F14: =IFERROR(SUMIFS('Tenant Data'!$I$2:$I$4674,'Tenant Data'!$A$2:$A$4674,A14,'Tenant Data'!$B$2:$B$4674,$B$3),"") -> 0 | G14: =IFERROR(SUMIFS('Tenant Data'!$J$2:$J$4674,'Tenant Data'!$A$2:$A$4674,A14,'Tenant Data'!$B$2:$B$4674,$B$3),"") -> 0
A15: Bridge Street Towne Centre | B15: ='Property Summary'!B9 -> Y | C15: =IFERROR(SUMIFS('Tenant Data'!$E$2:$E$4674,'Tenant Data'!$A$2:$A$4674,A15,'Tenant Data'!$B$2:$B$4674,$B$3),"") -> 0 | D15: =IFERROR(SUMIFS('Tenant Data'!$F$2:$F$4674,'Tenant Data'!$A$2:$A$4674,A15,'Tenant Data'!$B$2:$B$4674,$B$3),"") -> 0 | E15: =IFERROR(IF(C15>0,D15/C15,""),"") | F15: =IFERROR(SUMIFS('Tenant Data'!$I$2:$I$4674,'Tenant Data'!$A$2:$A$4674,A15,'Tenant Data'!$B$2:$B$4674,$B$3),"") -> 0 | G15: =IFERROR(SUMIFS('Tenant Data'!$J$2:$J$4674,'Tenant Data'!$A$2:$A$4674,A15,'Tenant Data'!$B$2:$B$4674,$B$3),"") -> 0
A16: Bridgewater Commons | B16: ='Property Summary'!B10 -> Y | C16: =IFERROR(SUMIFS('Tenant Data'!$E$2:$E$4674,'Tenant Data'!$A$2:$A$4674,A16,'Tenant Data'!$B$2:$B$4674,$B$3),"") -> 806 | D16: =IFERROR(SUMIFS('Tenant Data'!$F$2:$F$4674,'Tenant Data'!$A$2:$A$4674,A16,'Tenant Data'!$B$2:$B$4674,$B$3),"") -> 669303 | E16: =IFERROR(IF(C16>0,D16/C16,""),"") -> 830.40074 | F16: =IFERROR(SUMIFS('Tenant Data'!$I$2:$I$4674,'Tenant Data'!$A$2:$A$4674,A16,'Tenant Data'!$B$2:$B$4674,$B$3),"") -> 116.19141 | G16: =IFERROR(SUMIFS('Tenant Data'!$J$2:$J$4674,'Tenant Data'!$A$2:$A$4674,A16,'Tenant Data'!$B$2:$B$4674,$B$3),"") -> 0.1399221
A17: Capital City Mall | B17: ='Property Summary'!B11 -> Y | C17: =IFERROR(SUMIFS('Tenant Data'!$E$2:$E$4674,'Tenant Data'!$A$2:$A$4674,A17,'Tenant Data'!$B$2:$B$4674,$B$3),"") -> 800 | D17: =IFERROR(SUMIFS('Tenant Data'!$F$2:$F$4674,'Tenant Data'!$A$2:$A$4674,A17,'Tenant Data'!$B$2:$B$4674,$B$3),"") -> 478642.84 | E17: =IFERROR(IF(C17>0,D17/C17,""),"") -> 598.30355 | F17: =IFERROR(SUMIFS('Tenant Data'!$I$2:$I$4674,'Tenant Data'!$A$2:$A$4674,A17,'Tenant Data'!$B$2:$B$4674,$B$3),"") -> 112.725 | G17: =IFERROR(SUMIFS('Tenant Data'!$J$2:$J$4674,'Tenant Data'!$A$2:$A$4674,A17,'Tenant Data'!$B$2:$B$4674,$B$3),"") -> 0.18840771
A18: Coastal Grand Mall | B18: ='Property Summary'!B12 -> Y | C18: =IFERROR(SUMIFS('Tenant Data'!$E$2:$E$4674,'Tenant Data'!$A$2:$A$4674,A18,'Tenant Data'!$B$2:$B$4674,$B$3),"") -> 1970 | D18: =IFERROR(SUMIFS('Tenant Data'!$F$2:$F$4674,'Tenant Data'!$A$2:$A$4674,A18,'Tenant Data'!$B$2:$B$4674,$B$3),"") -> 492166.72 | E18: =IFERROR(IF(C18>0,D18/C18,""),"") -> 249.83082 | F18: =IFERROR(SUMIFS('Tenant Data'!$I$2:$I$4674,'Tenant Data'!$A$2:$A$4674,A18,'Tenant Data'!$B$2:$B$4674,$B$3),"") -> 28.446703 | G18: =IFERROR(SUMIFS('Tenant Data'!$J$2:$J$4674,'Tenant Data'!$A$2:$A$4674,A18,'Tenant Data'!$B$2:$B$4674,$B$3),"") -> 0.11386387
A19: CoolSprings Galleria | B19: ='Property Summary'!B13 -> Y | C19: =IFERROR(SUMIFS('Tenant Data'!$E$2:$E$4674,'Tenant Data'!$A$2:$A$4674,A19,'Tenant Data'!$B$2:$B$4674,$B$3),"") -> 631 | D19: =IFERROR(SUMIFS('Tenant Data'!$F$2:$F$4674,'Tenant Data'!$A$2:$A$4674,A19,'Tenant Data'!$B$2:$B$4674,$B$3),"") -> 493135.42 | E19: =IFERROR(IF(C19>0,D19/C19,""),"") -> 781.51414 | F19: =IFERROR(SUMIFS('Tenant Data'!$I$2:$I$4674,'Tenant Data'!$A$2:$A$4674,A19,'Tenant Data'!$B$2:$B$4674,$B$3),"") -> 124.85835 | G19: =IFERROR(SUMIFS('Tenant Data'!$J$2:$J$4674,'Tenant Data'!$A$2:$A$4674,A19,'Tenant Data'!$B$2:$B$4674,$B$3),"") -> 0.15976467
... A55: Willow Grove Park | B55: ='Property Summary'!B49 -> Y | C55: =IFERROR(SUMIFS('Tenant Data'!$E$2:$E$4674,'Tenant Data'!$A$2:$A$4674,A55,'Tenant Data'!$B$2:$B$4674,$B$3),"") -> 738 | D55: =IFERROR(SUMIFS('Tenant Data'!$F$2:$F$4674,'Tenant Data'!$A$2:$A$4674,A55,'Tenant Data'!$B$2:$B$4674,$B$3),"") -> 539559 | E55: =IFERROR(IF(C55>0,D55/C55,""),"") -> 731.10976 | F55: =IFERROR(SUMIFS('Tenant Data'!$I$2:$I$4674,'Tenant Data'!$A$2:$A$4674,A55,'Tenant Data'!$B$2:$B$4674,$B$3),"") -> 136.57 | G55: =IFERROR(SUMIFS('Tenant Data'!$J$2:$J$4674,'Tenant Data'!$A$2:$A$4674,A55,'Tenant Data'!$B$2:$B$4674,$B$3),"") -> 0.1868
A56: Total / Weighted Avg | C56: =SUMPRODUCT((B8:B55="Y")*(C8:C55<>"")*C8:C55) -> 30138 | D56: =SUMPRODUCT((B8:B55="Y")*(D8:D55<>"")*D8:D55) -> 13793981 | E56: =IFERROR(D56/C56,"") -> 457.69397
A58: Sales PSF Ranking (Highest to Lowest)
A59: Rank | B59: Property | C59: Sales PSF
A60: 1 | B60: =IFERROR(INDEX($A$8:$A$55,MATCH(LARGE($E$8:$E$55,1),$E$8:$E$55,0)),"") -> Galleria at Tyler | C60: =IFERROR(LARGE($E$8:$E$55,1),"") -> 934.94586
A61: 2 | B61: =IFERROR(INDEX($A$8:$A$55,MATCH(LARGE($E$8:$E$55,2),$E$8:$E$55,0)),"") -> Fayette Mall | C61: =IFERROR(LARGE($E$8:$E$55,2),"") -> 914.33705
A62: 3 | B62: =IFERROR(INDEX($A$8:$A$55,MATCH(LARGE($E$8:$E$55,3),$E$8:$E$55,0)),"") -> Oak Park Mall | C62: =IFERROR(LARGE($E$8:$E$55,3),"") -> 842.28191
A63: 4 | B63: =IFERROR(INDEX($A$8:$A$55,MATCH(LARGE($E$8:$E$55,4),$E$8:$E$55,0)),"") -> Bridgewater Commons | C63: =IFERROR(LARGE($E$8:$E$55,4),"") -> 830.40074
A64: 5 | B64: =IFERROR(INDEX($A$8:$A$55,MATCH(LARGE($E$8:$E$55,5),$E$8:$E$55,0)),"") -> Hamilton Place Mall | C64: =IFERROR(LARGE($E$8:$E$55,5),"") -> 788.2124
A65: 6 | B65: =IFERROR(INDEX($A$8:$A$55,MATCH(LARGE($E$8:$E$55,6),$E$8:$E$55,0)),"") -> West Towne Mall | C65: =IFERROR(LARGE($E$8:$E$55,6),"") -> 781.69972
A66: 7 | B66: =IFERROR(INDEX($A$8:$A$55,MATCH(LARGE($E$8:$E$55,7),$E$8:$E$55,0)),"") -> CoolSprings Galleria | C66: =IFERROR(LARGE($E$8:$E$55,7),"") -> 781.51414
A67: 8 | B67: =IFERROR(INDEX($A$8:$A$55,MATCH(LARGE($E$8:$E$55,8),$E$8:$E$55,0)),"") -> Willow Grove Park | C67: =IFERROR(LARGE($E$8:$E$55,8),"") -> 731.10976
A68: 9 | B68: =IFERROR(INDEX($A$8:$A$55,MATCH(LARGE($E$8:$E$55,9),$E$8:$E$55,0)),"") -> Crabtree Valley Mall | C68: =IFERROR(LARGE($E$8:$E$55,9),"") -> 648.22177
A69: 10 | B69: =IFERROR(INDEX($A$8:$A$55,MATCH(LARGE($E$8:$E$55,10),$E$8:$E$55,0)),"") -> SouthPark Mall (OH) | C69: =IFERROR(LARGE($E$8:$E$55,10),"") -> 606.39334
A70: 11 | B70: =IFERROR(INDEX($A$8:$A$55,MATCH(LARGE($E$8:$E$55,11),$E$8:$E$55,0)),"") -> Capital City Mall | C70: =IFERROR(LARGE($E$8:$E$55,11),"") -> 598.30355
A71: 12 | B71: =IFERROR(INDEX($A$8:$A$55,MATCH(LARGE($E$8:$E$55,12),$E$8:$E$55,0)),"") -> Towson Town Center | C71: =IFERROR(LARGE($E$8:$E$55,12),"") -> 523.69713
A72: 13 | B72: =IFERROR(INDEX($A$8:$A$55,MATCH(LARGE($E$8:$E$55,13),$E$8:$E$55,0)),"") -> Providence Place | C72: =IFERROR(LARGE($E$8:$E$55,13),"") -> 519.6
A73: 14 | B73: =IFERROR(INDEX($A$8:$A$55,MATCH(LARGE($E$8:$E$55,14),$E$8:$E$55,0)),"") -> Clackamas Town Center | C73: =IFERROR(LARGE($E$8:$E$55,14),"") -> 517.00679
A74: 15 | B74: =IFERROR(INDEX($A$8:$A$55,MATCH(LARGE($E$8:$E$55,15),$E$8:$E$55,0)),"") -> Staten Island Mall | C74: =IFERROR(LARGE($E$8:$E$55,15),"") -> 507.52088
A75: 16 | B75: =IFERROR(INDEX($A$8:$A$55,MATCH(LARGE($E$8:$E$55,16),$E$8:$E$55,0)),"") -> West County Center | C75: =IFERROR(LARGE($E$8:$E$55,16),"") -> 477.68451
A76: 17 | B76: =IFERROR(INDEX($A$8:$A$55,MATCH(LARGE($E$8:$E$55,17),$E$8:$E$55,0)),"") -> Palisades Center | C76: =IFERROR(LARGE($E$8:$E$55,17),"") -> 467.76156
A77: 18 | B77: =IFERROR(INDEX($A$8:$A$55,MATCH(LARGE($E$8:$E$55,18),$E$8:$E$55,0)),"") -> SoNo Collection | C77: =IFERROR(LARGE($E$8:$E$55,18),"") -> 465.7367
A78: 19 | B78: =IFERROR(INDEX($A$8:$A$55,MATCH(LARGE($E$8:$E$55,19),$E$8:$E$55,0)),"") -> Crossgates Center | C78: =IFERROR(LARGE($E$8:$E$55,19),"") -> 463.83976
...

Sheet Category Lookup
A1: Category Sales PSF Summary
A3: Select Category: | B3: Apparel
A4: # Properties with this Category: | B4: =COUNTIF(C7:C54,">0") -> 48
A6: Property | B6: Include | C6: Tenants in Cat | D6: Total Cat SF | E6: Total Cat Sales | F6: Wtd Sales PSF
A7: Clackamas Town Center | B7: ='Property Summary'!B2 -> Y | C7: =COUNTIFS('Tenant Data'!$A$2:$A$4674,"Clackamas Town Center",'Tenant Data'!$D$2:$D$4674,$B$3,'Tenant Data'!$F$2:$F$4674,">0",'Tenant Data'!$E$2:$E$4674,"<10000") -> 25 | D7: =SUMIFS('Tenant Data'!$E$2:$E$4674,'Tenant Data'!$A$2:$A$4674,"Clackamas Town Center",'Tenant Data'!$D$2:$D$4674,$B$3,'Tenant Data'!$F$2:$F$4674,">0",'Tenant Data'!$E$2:$E$4674,"<10000") -> 95702 | E7: =SUMIFS('Tenant Data'!$F$2:$F$4674,'Tenant Data'!$A$2:$A$4674,"Clackamas Town Center",'Tenant Data'!$D$2:$D$4674,$B$3,'Tenant Data'!$E$2:$E$4674,"<10000") -> 39543528 | F7: =IFERROR(E7/D7,"") -> 413.19437
A8: Annapolis Mall | B8: ='Property Summary'!B3 -> Y | C8: =COUNTIFS('Tenant Data'!$A$2:$A$4674,"Annapolis Mall",'Tenant Data'!$D$2:$D$4674,$B$3,'Tenant Data'!$F$2:$F$4674,">0",'Tenant Data'!$E$2:$E$4674,"<10000") -> 36 | D8: =SUMIFS('Tenant Data'!$E$2:$E$4674,'Tenant Data'!$A$2:$A$4674,"Annapolis Mall",'Tenant Data'!$D$2:$D$4674,$B$3,'Tenant Data'!$F$2:$F$4674,">0",'Tenant Data'!$E$2:$E$4674,"<10000") -> 124472 | E8: =SUMIFS('Tenant Data'!$F$2:$F$4674,'Tenant Data'!$A$2:$A$4674,"Annapolis Mall",'Tenant Data'!$D$2:$D$4674,$B$3,'Tenant Data'!$E$2:$E$4674,"<10000") -> 40670815 | F8: =IFERROR(E8/D8,"") -> 326.7467
A9: Annapolis Town Center | B9: ='Property Summary'!B4 -> Y | C9: =COUNTIFS('Tenant Data'!$A$2:$A$4674,"Annapolis Town Center",'Tenant Data'!$D$2:$D$4674,$B$3,'Tenant Data'!$F$2:$F$4674,">0",'Tenant Data'!$E$2:$E$4674,"<10000") -> 2 | D9: =SUMIFS('Tenant Data'!$E$2:$E$4674,'Tenant Data'!$A$2:$A$4674,"Annapolis Town Center",'Tenant Data'!$D$2:$D$4674,$B$3,'Tenant Data'!$F$2:$F$4674,">0",'Tenant Data'!$E$2:$E$4674,"<10000") -> 7793 | E9: =SUMIFS('Tenant Data'!$F$2:$F$4674,'Tenant Data'!$A$2:$A$4674,"Annapolis Town Center",'Tenant Data'!$D$2:$D$4674,$B$3,'Tenant Data'!$E$2:$E$4674,"<10000") -> 3315511 | F9: =IFERROR(E9/D9,"") -> 425.44732
A10: Arden Fair Mall | B10: ='Property Summary'!B5 -> Y | C10: =COUNTIFS('Tenant Data'!$A$2:$A$4674,"Arden Fair Mall",'Tenant Data'!$D$2:$D$4674,$B$3,'Tenant Data'!$F$2:$F$4674,">0",'Tenant Data'!$E$2:$E$4674,"<10000") -> 32 | D10: =SUMIFS('Tenant Data'!$E$2:$E$4674,'Tenant Data'!$A$2:$A$4674,"Arden Fair Mall",'Tenant Data'!$D$2:$D$4674,$B$3,'Tenant Data'!$F$2:$F$4674,">0",'Tenant Data'!$E$2:$E$4674,"<10000") -> 112833 | E10: =SUMIFS('Tenant Data'!$F$2:$F$4674,'Tenant Data'!$A$2:$A$4674,"Arden Fair Mall",'Tenant Data'!$D$2:$D$4674,$B$3,'Tenant Data'!$E$2:$E$4674,"<10000") -> 58828912 | F10: =IFERROR(E10/D10,"") -> 521.38038
A11: Belmar | B11: ='Property Summary'!B6 -> Y | C11: =COUNTIFS('Tenant Data'!$A$2:$A$4674,"Belmar",'Tenant Data'!$D$2:$D$4674,$B$3,'Tenant Data'!$F$2:$F$4674,">0",'Tenant Data'!$E$2:$E$4674,"<10000") -> 5 | D11: =SUMIFS('Tenant Data'!$E$2:$E$4674,'Tenant Data'!$A$2:$A$4674,"Belmar",'Tenant Data'!$D$2:$D$4674,$B$3,'Tenant Data'!$F$2:$F$4674,">0",'Tenant Data'!$E$2:$E$4674,"<10000") -> 19325 | E11: =SUMIFS('Tenant Data'!$F$2:$F$4674,'Tenant Data'!$A$2:$A$4674,"Belmar",'Tenant Data'!$D$2:$D$4674,$B$3,'Tenant Data'!$E$2:$E$4674,"<10000") -> 3468669.8 | F11: =IFERROR(E11/D11,"") -> 179.49132
A12: Brandon Exchange | B12: ='Property Summary'!B7 -> Y | C12: =COUNTIFS('Tenant Data'!$A$2:$A$4674,"Brandon Exchange",'Tenant Data'!$D$2:$D$4674,$B$3,'Tenant Data'!$F$2:$F$4674,">0",'Tenant Data'!$E$2:$E$4674,"<10000") -> 32 | D12: =SUMIFS('Tenant Data'!$E$2:$E$4674,'Tenant Data'!$A$2:$A$4674,"Brandon Exchange",'Tenant Data'!$D$2:$D$4674,$B$3,'Tenant Data'!$F$2:$F$4674,">0",'Tenant Data'!$E$2:$E$4674,"<10000") -> 128917 | E12: =SUMIFS('Tenant Data'!$F$2:$F$4674,'Tenant Data'!$A$2:$A$4674,"Brandon Exchange",'Tenant Data'!$D$2:$D$4674,$B$3,'Tenant Data'!$E$2:$E$4674,"<10000") -> 52760542 | F12: =IFERROR(E12/D12,"") -> 409.25977
A13: Briarwood Mall | B13: ='Property Summary'!B8 -> Y | C13: =COUNTIFS('Tenant Data'!$A$2:$A$4674,"Briarwood Mall",'Tenant Data'!$D$2:$D$4674,$B$3,'Tenant Data'!$F$2:$F$4674,">0",'Tenant Data'!$E$2:$E$4674,"<10000") -> 25 | D13: =SUMIFS('Tenant Data'!$E$2:$E$4674,'Tenant Data'!$A$2:$A$4674,"Briarwood Mall",'Tenant Data'!$D$2:$D$4674,$B$3,'Tenant Data'!$F$2:$F$4674,">0",'Tenant Data'!$E$2:$E$4674,"<10000") -> 98694 | E13: =SUMIFS('Tenant Data'!$F$2:$F$4674,'Tenant Data'!$A$2:$A$4674,"Briarwood Mall",'Tenant Data'!$D$2:$D$4674,$B$3,'Tenant Data'!$E$2:$E$4674,"<10000") -> 2461300 | F13: =IFERROR(E13/D13,"") -> 24.938699
A14: Bridge Street Towne Centre | B14: ='Property Summary'!B9 -> Y | C14: =COUNTIFS('Tenant Data'!$A$2:$A$4674,"Bridge Street Towne Centre",'Tenant Data'!$D$2:$D$4674,$B$3,'Tenant Data'!$F$2:$F$4674,">0",'Tenant Data'!$E$2:$E$4674,"<10000") -> 16 | D14: =SUMIFS('Tenant Data'!$E$2:$E$4674,'Tenant Data'!$A$2:$A$4674,"Bridge Street Towne Centre",'Tenant Data'!$D$2:$D$4674,$B$3,'Tenant Data'!$F$2:$F$4674,">0",'Tenant Data'!$E$2:$E$4674,"<10000") -> 67517 | E14: =SUMIFS('Tenant Data'!$F$2:$F$4674,'Tenant Data'!$A$2:$A$4674,"Bridge Street Towne Centre",'Tenant Data'!$D$2:$D$4674,$B$3,'Tenant Data'!$E$2:$E$4674,"<10000") -> 28653133 | F14: =IFERROR(E14/D14,"") -> 424.38398
A15: Bridgewater Commons | B15: ='Property Summary'!B10 -> Y | C15: =COUNTIFS('Tenant Data'!$A$2:$A$4674,"Bridgewater Commons",'Tenant Data'!$D$2:$D$4674,$B$3,'Tenant Data'!$F$2:$F$4674,">0",'Tenant Data'!$E$2:$E$4674,"<10000") -> 39 | D15: =SUMIFS('Tenant Data'!$E$2:$E$4674,'Tenant Data'!$A$2:$A$4674,"Bridgewater Commons",'Tenant Data'!$D$2:$D$4674,$B$3,'Tenant Data'!$F$2:$F$4674,">0",'Tenant Data'!$E$2:$E$4674,"<10000") -> 129945 | E15: =SUMIFS('Tenant Data'!$F$2:$F$4674,'Tenant Data'!$A$2:$A$4674,"Bridgewater Commons",'Tenant Data'!$D$2:$D$4674,$B$3,'Tenant Data'!$E$2:$E$4674,"<10000") -> 59198033 | F15: =IFERROR(E15/D15,"") -> 455.56222
A16: Capital City Mall | B16: ='Property Summary'!B11 -> Y | C16: =COUNTIFS('Tenant Data'!$A$2:$A$4674,"Capital City Mall",'Tenant Data'!$D$2:$D$4674,$B$3,'Tenant Data'!$F$2:$F$4674,">0",'Tenant Data'!$E$2:$E$4674,"<10000") -> 16 | D16: =SUMIFS('Tenant Data'!$E$2:$E$4674,'Tenant Data'!$A$2:$A$4674,"Capital City Mall",'Tenant Data'!$D$2:$D$4674,$B$3,'Tenant Data'!$F$2:$F$4674,">0",'Tenant Data'!$E$2:$E$4674,"<10000") -> 61066 | E16: =SUMIFS('Tenant Data'!$F$2:$F$4674,'Tenant Data'!$A$2:$A$4674,"Capital City Mall",'Tenant Data'!$D$2:$D$4674,$B$3,'Tenant Data'!$E$2:$E$4674,"<10000") -> 21246686 | F16: =IFERROR(E16/D16,"") -> 347.92987
A17: Coastal Grand Mall | B17: ='Property Summary'!B12 -> Y | C17: =COUNTIFS('Tenant Data'!$A$2:$A$4674,"Coastal Grand Mall",'Tenant Data'!$D$2:$D$4674,$B$3,'Tenant Data'!$F$2:$F$4674,">0",'Tenant Data'!$E$2:$E$4674,"<10000") -> 22 | D17: =SUMIFS('Tenant Data'!$E$2:$E$4674,'Tenant Data'!$A$2:$A$4674,"Coastal Grand Mall",'Tenant Data'!$D$2:$D$4674,$B$3,'Tenant Data'!$F$2:$F$4674,">0",'Tenant Data'!$E$2:$E$4674,"<10000") -> 99474 | E17: =SUMIFS('Tenant Data'!$F$2:$F$4674,'Tenant Data'!$A$2:$A$4674,"Coastal Grand Mall",'Tenant Data'!$D$2:$D$4674,$B$3,'Tenant Data'!$E$2:$E$4674,"<10000") -> 30000421 | F17: =IFERROR(E17/D17,"") -> 301.59058
A18: CoolSprings Galleria | B18: ='Property Summary'!B13 -> Y | C18: =COUNTIFS('Tenant Data'!$A$2:$A$4674,"CoolSprings Galleria",'Tenant Data'!$D$2:$D$4674,$B$3,'Tenant Data'!$F$2:$F$4674,">0",'Tenant Data'!$E$2:$E$4674,"<10000") -> 33 | D18: =SUMIFS('Tenant Data'!$E$2:$E$4674,'Tenant Data'!$A$2:$A$4674,"CoolSprings Galleria",'Tenant Data'!$D$2:$D$4674,$B$3,'Tenant Data'!$F$2:$F$4674,">0",'Tenant Data'!$E$2:$E$4674,"<10000") -> 124374 | E18: =SUMIFS('Tenant Data'!$F$2:$F$4674,'Tenant Data'!$A$2:$A$4674,"CoolSprings Galleria",'Tenant Data'!$D$2:$D$4674,$B$3,'Tenant Data'!$E$2:$E$4674,"<10000") -> 47933250 | F18: =IFERROR(E18/D18,"") -> 385.39606
A19: Crabtree Valley Mall | B19: ='Property Summary'!B14 -> Y | C19: =COUNTIFS('Tenant Data'!$A$2:$A$4674,"Crabtree Valley Mall",'Tenant Data'!$D$2:$D$4674,$B$3,'Tenant Data'!$F$2:$F$4674,">0",'Tenant Data'!$E$2:$E$4674,"<10000") -> 32 | D19: =SUMIFS('Tenant Data'!$E$2:$E$4674,'Tenant Data'!$A$2:$A$4674,"Crabtree Valley Mall",'Tenant Data'!$D$2:$D$4674,$B$3,'Tenant Data'!$F$2:$F$4674,">0",'Tenant Data'!$E$2:$E$4674,"<10000") -> 122540 | E19: =SUMIFS('Tenant Data'!$F$2:$F$4674,'Tenant Data'!$A$2:$A$4674,"Crabtree Valley Mall",'Tenant Data'!$D$2:$D$4674,$B$3,'Tenant Data'!$E$2:$E$4674,"<10000") -> 65407476 | F19: =IFERROR(E19/D19,"") -> 533.76429
A20: Cross Creek Mall | B20: ='Property Summary'!B15 -> Y | C20: =COUNTIFS('Tenant Data'!$A$2:$A$4674,"Cross Creek Mall",'Tenant Data'!$D$2:$D$4674,$B$3,'Tenant Data'!$F$2:$F$4674,">0",'Tenant Data'!$E$2:$E$4674,"<10000") -> 24 | D20: =SUMIFS('Tenant Data'!$E$2:$E$4674,'Tenant Data'!$A$2:$A$4674,"Cross Creek Mall",'Tenant Data'!$D$2:$D$4674,$B$3,'Tenant Data'!$F$2:$F$4674,">0",'Tenant Data'!$E$2:$E$4674,"<10000") -> 102781 | E20: =SUMIFS('Tenant Data'!$F$2:$F$4674,'Tenant Data'!$A$2:$A$4674,"Cross Creek Mall",'Tenant Data'!$D$2:$D$4674,$B$3,'Tenant Data'!$E$2:$E$4674,"<10000") -> 33623800 | F20: =IFERROR(E20/D20,"") -> 327.14023
A21: Crossgates Center | B21: ='Property Summary'!B16 -> Y | C21: =COUNTIFS('Tenant Data'!$A$2:$A$4674,"Crossgates Center",'Tenant Data'!$D$2:$D$4674,$B$3,'Tenant Data'!$F$2:$F$4674,">0",'Tenant Data'!$E$2:$E$4674,"<10000") -> 27 | D21: =SUMIFS('Tenant Data'!$E$2:$E$4674,'Tenant Data'!$A$2:$A$4674,"Crossgates Center",'Tenant Data'!$D$2:$D$4674,$B$3,'Tenant Data'!$F$2:$F$4674,">0",'Tenant Data'!$E$2:$E$4674,"<10000") -> 126360 | E21: =SUMIFS('Tenant Data'!$F$2:$F$4674,'Tenant Data'!$A$2:$A$4674,"Crossgates Center",'Tenant Data'!$D$2:$D$4674,$B$3,'Tenant Data'!$E$2:$E$4674,"<10000") -> 52428213 | F21: =IFERROR(E21/D21,"") -> 414.91147
A22: Destiny USA | B22: ='Property Summary'!B17 -> Y | C22: =COUNTIFS('Tenant Data'!$A$2:$A$4674,"Destiny USA",'Tenant Data'!$D$2:$D$4674,$B$3,'Tenant Data'!$F$2:$F$4674,">0",'Tenant Data'!$E$2:$E$4674,"<10000") -> 41 | D22: =SUMIFS('Tenant Data'!$E$2:$E$4674,'Tenant Data'!$A$2:$A$4674,"Destiny USA",'Tenant Data'!$D$2:$D$4674,$B$3,'Tenant Data'!$F$2:$F$4674,">0",'Tenant Data'!$E$2:$E$4674,"<10000") -> 177924 | E22: =SUMIFS('Tenant Data'!$F$2:$F$4674,'Tenant Data'!$A$2:$A$4674,"Destiny USA",'Tenant Data'!$D$2:$D$4674,$B$3,'Tenant Data'!$E$2:$E$4674,"<10000") -> 59494876 | F22: =IFERROR(E22/D22,"") -> 334.38365
A23: Fayette Mall | B23: ='Property Summary'!B18 -> Y | C23: =COUNTIFS('Tenant Data'!$A$2:$A$4674,"Fayette Mall",'Tenant Data'!$D$2:$D$4674,$B$3,'Tenant Data'!$F$2:$F$4674,">0",'Tenant Data'!$E$2:$E$4674,"<10000") -> 35 | D23: =SUMIFS('Tenant Data'!$E$2:$E$4674,'Tenant Data'!$A$2:$A$4674,"Fayette Mall",'Tenant Data'!$D$2:$D$4674,$B$3,'Tenant Data'!$F$2:$F$4674,">0",'Tenant Data'!$E$2:$E$4674,"<10000") -> 147018 | E23: =SUMIFS('Tenant Data'!$F$2:$F$4674,'Tenant Data'!$A$2:$A$4674,"Fayette Mall",'Tenant Data'!$D$2:$D$4674,$B$3,'Tenant Data'!$E$2:$E$4674,"<10000") -> 59566882 | F23: =IFERROR(E23/D23,"") -> 405.16728
A24: Galleria at Tyler | B24: ='Property Summary'!B19 -> Y | C24: =COUNTIFS('Tenant Data'!$A$2:$A$4674,"Galleria at Tyler",'Tenant Data'!$D$2:$D$4674,$B$3,'Tenant Data'!$F$2:$F$4674,">0",'Tenant Data'!$E$2:$E$4674,"<10000") -> 29 | D24: =SUMIFS('Tenant Data'!$E$2:$E$4674,'Tenant Data'!$A$2:$A$4674,"Galleria at Tyler",'Tenant Data'!$D$2:$D$4674,$B$3,'Tenant Data'!$F$2:$F$4674,">0",'Tenant Data'!$E$2:$E$4674,"<10000") -> 102805 | E24: =SUMIFS('Tenant Data'!$F$2:$F$4674,'Tenant Data'!$A$2:$A$4674,"Galleria at Tyler",'Tenant Data'!$D$2:$D$4674,$B$3,'Tenant Data'!$E$2:$E$4674,"<10000") -> 32783728 | F24: =IFERROR(E24/D24,"") -> 318.89235
A25: Hamilton Place Mall | B25: ='Property Summary'!B20 -> Y | C25: =COUNTIFS('Tenant Data'!$A$2:$A$4674,"Hamilton Place Mall",'Tenant Data'!$D$2:$D$4674,$B$3,'Tenant Data'!$F$2:$F$4674,">0",'Tenant Data'!$E$2:$E$4674,"<10000") -> 27 | D25: =SUMIFS('Tenant Data'!$E$2:$E$4674,'Tenant Data'!$A$2:$A$4674,"Hamilton Place Mall",'Tenant Data'!$D$2:$D$4674,$B$3,'Tenant Data'!$F$2:$F$4674,">0",'Tenant Data'!$E$2:$E$4674,"<10000") -> 121920 | E25: =SUMIFS('Tenant Data'!$F$2:$F$4674,'Tenant Data'!$A$2:$A$4674,"Hamilton Place Mall",'Tenant Data'!$D$2:$D$4674,$B$3,'Tenant Data'!$E$2:$E$4674,"<10000") -> 44256196 | F25: =IFERROR(E25/D25,"") -> 362.99373
A26: Hanes Mall | B26: ='Property Summary'!B21 -> Y | C26: =COUNTIFS('Tenant Data'!$A$2:$A$4674,"Hanes Mall",'Tenant Data'!$D$2:$D$4674,$B$3,'Tenant Data'!$F$2:$F$4674,">0",'Tenant Data'!$E$2:$E$4674,"<10000") -> 26 | D26: =SUMIFS('Tenant Data'!$E$2:$E$4674,'Tenant Data'!$A$2:$A$4674,"Hanes Mall",'Tenant Data'!$D$2:$D$4674,$B$3,'Tenant Data'!$F$2:$F$4674,">0",'Tenant Data'!$E$2:$E$4674,"<10000") -> 114377 | E26: =SUMIFS('Tenant Data'!$F$2:$F$4674,'Tenant Data'!$A$2:$A$4674,"Hanes Mall",'Tenant Data'!$D$2:$D$4674,$B$3,'Tenant Data'!$E$2:$E$4674,"<10000") -> 34524103 | F26: =IFERROR(E26/D26,"") -> 301.8448
